Workbook

Sheet Leeme
A1: Modelo CODA-Rural: evaluación de la calidad de recursos educativos digitales en contextos de baja conectividad
A2: Autor: Jorge Guillermo Federico Castro Cervantes · Especialización en Aplicación de TIC para la Enseñanza, Universidad de Santander · Evaluación de Recursos Educativos Digitales · 2026
A4: Cómo usar este instrumento
A5: 1. Haga una copia de la hoja «Plantilla» y cámbiele el nombre por el del recurso.
A6: 2. Llene la ficha A (datos del recurso) y la lista B (pruebas de contexto: equipo con conexión, celular, modo avión, peso).
A7: 3. En la tabla C escriba un puntaje de 1 a 5 por criterio (o NA si no aplica) y la evidencia observada. Use la hoja «Rúbrica» para elegir el nivel.
A8: 4. El bloque D calcula solo: promedio por dimensión, índice global (IGC), nivel, decisión y regla de contexto.
A9: 5. Registre en E qué deben mejorar el recurso o su uso (aspectos técnicos, pedagógicos y comunicacionales).
A11: Convenciones
A12: Celdas con fondo amarillo: las llena el evaluador. Celdas con fondo gris: fórmulas, no se editan.
A13: Las hojas «Educ.ar» y «Scratch» son ejemplos llenos: la aplicación del Entregable 2.
A14: Escala: 1 Deficiente · 2 Insuficiente · 3 Aceptable · 4 Bueno · 5 Excelente · NA No aplica (no cuenta en el promedio).
... A17: Regla de contexto: si C11 o C12 obtiene 1 o 2, la decisión no puede ser «Recomendado»; pasa a «Recomendado con condiciones de uso» y el evaluador debe registrar un plan alterno.

Sheet Parametros
A1: Parámetros del modelo
A3: Dimensión | B3: Peso
A4: Pedagógica | B4: 0.4
A5: Comunicacional | B5: 0.25
A6: Técnica y de contexto | B6: 0.35
A7: Total | B7: =SUM(B4:B6) -> 1
A9: IGC mínimo | B9: Nivel | C9: Decisión
A10: 4 | B10: Alto | C10: Recomendado
A11: 3 | B11: Medio | C11: Recomendado con ajustes
A12: 1 | B12: Bajo | C12: No recomendado
A14: Los pesos son decisión del autor del modelo (justificación en el informe, sección Métrica o escala de valoración).

Sheet Rubrica
A1: Dim. | B1: Criterio | C1: Origen | D1: Indicadores observables | E1: 1 · Deficiente | F1: 2 · Insuficiente | G1: 3 · Aceptable | H1: 4 · Bueno | I1: 5 · Excelente
A2: Pedagógica | B2: C1. Objetivos y coherencia didáctica | C2: COdA 1 | D2: • El recurso declara objetivos o resultados de aprendizaje. • Contenidos, actividades y evaluación responden a esos objetivos y al nivel del grupo. | E2: No declara objetivos y no se identifica qué se aprende. | F2: Los objetivos se deducen, pero contenidos y actividades no se relacionan con ellos. | G2: Declara objetivos generales; parte de las actividades no se alinea o el destinatario es otro (p. ej., docentes). | H2: Declara objetivos y casi todo se alinea; requiere ajustes menores para el grado. | I2: Objetivos explícitos, alineados con contenidos, actividades y evaluación, y adecuados al grado sin ajustes.
A3: Pedagógica | B3: C2. Calidad de los contenidos | C3: COdA 2 | D3: • La información es correcta y su fuente es identificable. • Es vigente y sus ejemplos sirven en el contexto colombiano y rural. | E3: Tiene errores conceptuales o la fuente es desconocida. | F3: Es correcta, pero está desactualizada o incompleta en puntos clave. | G3: Es correcta y con fuente; varios ejemplos deben adaptarse al contexto. | H3: Es correcta, vigente y con fuente; algunos ejemplos deben adaptarse. | I3: Es correcta, vigente, de fuente institucional, y sus ejemplos se usan sin adaptar.
A4: Pedagógica | B4: C3. Reflexión, crítica e innovación | C4: COdA 3 + Reeves (rol del estudiante) | D4: • Plantea problemas, retos o preguntas abiertas. • El estudiante elabora un producto propio. | E4: Solo presenta información para leer. | F4: Solo hace preguntas de memoria. | G4: Pide reproducir pasos indicados (práctica guiada). | H4: Plantea retos o casos con más de una solución. | I4: El estudiante crea productos propios, los comparte y los mejora.
A5: Pedagógica | B5: C4. Interactividad y retroalimentación | C5: COdA 4 + Reeves (valor del error) | D5: • Incluye actividades en las que el sistema responde a lo que hace el estudiante. • La respuesta explica el error o muestra el resultado de inmediato. | E5: Lectura lineal, sin interacción. | F5: La interacción es solo de navegación (avanzar, ampliar); no hay actividades. | G5: Hay actividades con retroalimentación de acierto o error. | H5: La retroalimentación explica el error o el resultado se ve de inmediato. | I5: Retroalimentación inmediata y el recorrido se adapta a las decisiones del estudiante.
A6: Comunicacional | B6: C5. Motivación | C6: COdA 5 | D6: • Conecta con los intereses o la vida diaria del estudiante. • Incluye un reto, un juego o un producto que invita a continuar. | E6: No conecta con el estudiante. | F6: Usa ejemplos lejanos a su realidad. | G6: Es útil, pero nada invita a continuar. | H6: Es útil e incluye al menos un reto, juego o producto. | I6: La propia actividad (crear, jugar, compartir) genera deseo de continuar.
A7: Comunicacional | B7: C6. Formato y diseño | C7: COdA 6 | D7: • El texto es legible: tamaño y contraste suficientes. • Hay jerarquía visual y espacio en blanco; las imágenes cumplen una función. | E7: Ilegible o saturado. | F7: Se lee con esfuerzo; bloques densos de texto. | G7: Legible, con algunas pantallas saturadas. | H7: Legible y ordenado; las imágenes apoyan el contenido. | I7: Además, el diseño es consistente en todas las pantallas.
A8: Comunicacional | B8: C7. Usabilidad | C8: COdA 7 | D8: • El estudiante sabe cómo empezar y avanzar sin ayuda. • Siempre sabe dónde está y puede volver atrás. | E8: No logra usarlo sin ayuda constante. | F8: Necesita ayuda en varios pasos. | G8: Necesita ayuda solo al inicio. | H8: Lo usa solo, con instrucciones mínimas. | I8: Lo usa solo desde el primer intento; la navegación es clara y reversible.
A9: Comunicacional | B9: C8. Accesibilidad | C9: COdA 8 | D9: • Está en español, con lenguaje claro. • Ofrece alternativas: texto para audio o video, versión descargable, ajuste de tamaño. | E9: En otro idioma o con lenguaje inaccesible. | F9: En español, con lenguaje técnico y sin apoyos. | G9: En español claro, sin alternativas. | H9: En español claro y con al menos una alternativa. | I9: En español claro y con varias alternativas verificadas.
A10: Técnica y de contexto | B10: C9. Reusabilidad y licencia | C10: COdA 9 | D10: • Declara una licencia abierta. • Se puede descargar, adaptar o remezclar. | E10: Sin licencia o con todos los derechos reservados. | F10: Uso gratuito, pero sin licencia declarada. | G10: Licencia abierta que impide modificar (ND). | H10: Licencia abierta con restricciones (p. ej., NC) o sin archivo fuente editable. | I10: Licencia abierta que permite modificar y archivo fuente editable.
A11: Técnica y de contexto | B11: C10. Interoperabilidad | C11: COdA 10 + UNE 71362 | D11: • Se descarga o exporta en formatos abiertos o comunes. • Se integra al aula virtual institucional (enlace, incrustación o paquete estándar). | E11: Solo funciona dentro de su plataforma, sin enlace estable. | F11: Tiene enlace estable, sin descarga. | G11: Enlace estable y descarga en formato común (PDF, imagen) o incrustable. | H11: Exporta en un formato propio abierto y se puede incrustar. | I11: Se distribuye como paquete estándar (SCORM, IMS) o con metadatos estándar.
A12: Técnica y de contexto | B12: C11. Funcionamiento sin conexión | C12: Nuevo (contexto) | D12: • El recurso se puede descargar completo. • Después de la descarga, la actividad principal funciona en modo avión. | E12: Exige conexión permanente. | F12: Solo se descargan materiales de apoyo. | G12: Se descarga el contenido, pero la actividad principal exige conexión. | H12: La actividad principal funciona sin conexión, solo en algunos equipos de la institución. | I12: Funciona completo sin conexión en todos los equipos disponibles, incluido el celular.
A13: Técnica y de contexto | B13: C12. Funcionamiento en celular | C13: Nuevo (contexto) | D13: • La actividad principal se puede realizar en un celular Android. • El recurso es liviano o permite bajo consumo de datos. | E13: La actividad principal no se puede realizar en celular. | F13: Se ve en el celular, pero con fallas que impiden completarla. | G13: Se completa en el celular con dificultad (ampliar, desplazar de lado) o con alto consumo. | H13: Se completa en el celular con ajustes menores. | I13: Diseño adaptable: se completa sin dificultad y con bajo consumo.

Sheet Plantilla
A1: Instrumento CODA-Rural · Ficha de evaluación de un RED
A2: Amarillo: lo llena el evaluador · Gris: fórmula
A4: A. Identificación del recurso
A5: Nombre del RED
A6: Autor / repositorio
A7: Enlace
A8: Área y grado
A9: Evaluador y fecha
A11: B. Pruebas de contexto (registrar antes de puntuar)
A12: Prueba | B12: Qué se hace | D12: Resultado | F12: Observación
A13: P1 | B13: Abrir el recurso en un computador con conexión.
A14: P2 | B14: Abrir y usar la actividad principal en un celular Android.
A15: P3 | B15: Descargar el recurso y usarlo en modo avión.
A16: P4 | B16: Registrar el peso de la descarga o el consumo de datos.
A18: C. Rúbrica de valoración (1 a 5 o NA)
A19: Dimensión | B19: Criterio | C19: Indicadores observables | D19: Puntaje | E19: Nivel | F19: Evidencia observada
A20: Pedagógica | B20: C1. Objetivos y coherencia didáctica | C20: • El recurso declara objetivos o resultados de aprendizaje. • Contenidos, actividades y evaluación responden a esos objetivos y al nivel del grupo. | E20: =IF(D20="","",IF(D20="NA","No aplica",INDEX({"Deficiente","Insuficiente","Aceptable","Bueno","Excelente"},D20)))
A21: Pedagógica | B21: C2. Calidad de los contenidos | C21: • La información es correcta y su fuente es identificable. • Es vigente y sus ejemplos sirven en el contexto colombiano y rural. | E21: =IF(D21="","",IF(D21="NA","No aplica",INDEX({"Deficiente","Insuficiente","Aceptable","Bueno","Excelente"},D21)))
A22: Pedagógica | B22: C3. Reflexión, crítica e innovación | C22: • Plantea problemas, retos o preguntas abiertas. • El estudiante elabora un producto propio. | E22: =IF(D22="","",IF(D22="NA","No aplica",INDEX({"Deficiente","Insuficiente","Aceptable","Bueno","Excelente"},D22)))
A23: Pedagógica | B23: C4. Interactividad y retroalimentación | C23: • Incluye actividades en las que el sistema responde a lo que hace el estudiante. • La respuesta explica el error o muestra el resultado de inmediato. | E23: =IF(D23="","",IF(D23="NA","No aplica",INDEX({"Deficiente","Insuficiente","Aceptable","Bueno","Excelente"},D23)))
A24: Comunicacional | B24: C5. Motivación | C24: • Conecta con los intereses o la vida diaria del estudiante. • Incluye un reto, un juego o un producto que invita a continuar. | E24: =IF(D24="","",IF(D24="NA","No aplica",INDEX({"Deficiente","Insuficiente","Aceptable","Bueno","Excelente"},D24)))
A25: Comunicacional | B25: C6. Formato y diseño | C25: • El texto es legible: tamaño y contraste suficientes. • Hay jerarquía visual y espacio en blanco; las imágenes cumplen una función. | E25: =IF(D25="","",IF(D25="NA","No aplica",INDEX({"Deficiente","Insuficiente","Aceptable","Bueno","Excelente"},D25)))
A26: Comunicacional | B26: C7. Usabilidad | C26: • El estudiante sabe cómo empezar y avanzar sin ayuda. • Siempre sabe dónde está y puede volver atrás. | E26: =IF(D26="","",IF(D26="NA","No aplica",INDEX({"Deficiente","Insuficiente","Aceptable","Bueno","Excelente"},D26)))
A27: Comunicacional | B27: C8. Accesibilidad | C27: • Está en español, con lenguaje claro. • Ofrece alternativas: texto para audio o video, versión descargable, ajuste de tamaño. | E27: =IF(D27="","",IF(D27="NA","No aplica",INDEX({"Deficiente","Insuficiente","Aceptable","Bueno","Excelente"},D27)))
A28: Técnica y de contexto | B28: C9. Reusabilidad y licencia | C28: • Declara una licencia abierta. • Se puede descargar, adaptar o remezclar. | E28: =IF(D28="","",IF(D28="NA","No aplica",INDEX({"Deficiente","Insuficiente","Aceptable","Bueno","Excelente"},D28)))
A29: Técnica y de contexto | B29: C10. Interoperabilidad | C29: • Se descarga o exporta en formatos abiertos o comunes. • Se integra al aula virtual institucional (enlace, incrustación o paquete estándar). | E29: =IF(D29="","",IF(D29="NA","No aplica",INDEX({"Deficiente","Insuficiente","Aceptable","Bueno","Excelente"},D29)))
A30: Técnica y de contexto | B30: C11. Funcionamiento sin conexión | C30: • El recurso se puede descargar completo. • Después de la descarga, la actividad principal funciona en modo avión. | E30: =IF(D30="","",IF(D30="NA","No aplica",INDEX({"Deficiente","Insuficiente","Aceptable","Bueno","Excelente"},D30)))
A31: Técnica y de contexto | B31: C12. Funcionamiento en celular | C31: • La actividad principal se puede realizar en un celular Android. • El recurso es liviano o permite bajo consumo de datos. | E31: =IF(D31="","",IF(D31="NA","No aplica",INDEX({"Deficiente","Insuficiente","Aceptable","Bueno","Excelente"},D31)))
A33: D. Resultados (cálculo automático)
A34: Pedagógica | B34: =Parametros!B4 -> 0.4 | C34: =IFERROR(AVERAGEIF($A$20:$A$31,A34,$D$20:$D$31),"") | D34: ← promedio por dimensión
A35: Comunicacional | B35: =Parametros!B5 -> 0.25 | C35: =IFERROR(AVERAGEIF($A$20:$A$31,A35,$D$20:$D$31),"")
A36: Técnica y de contexto | B36: =Parametros!B6 -> 0.35 | C36: =IFERROR(AVERAGEIF($A$20:$A$31,A36,$D$20:$D$31),"")
A37: Índice global (IGC) | C37: =IF(COUNT(D20:D31)=0,"",IFERROR(SUMPRODUCT(B34:B36,C34:C36)/SUM(B34:B36),""))
A38: Porcentaje | C38: =IFERROR(C37/5,"")
A39: Nivel | C39: =IF(C37="","",IF(C37>=Parametros!$A$10,Parametros!$B$10,IF(C37>=Parametros!$A$11,Parametros!$B$11,Parametros!$B$12)))
A40: Regla de contexto | C40: =IF(C37="","",IF(OR(AND(ISNUMBER(D30),D30<=2),AND(ISNUMBER(D31),D31<=2)),"Se activa (C11 o C12 ≤ 2)","No se activa"))
A41: Decisión | C41: =IF(C37="","",IF(C37>=Parametros!$A$10,IF(LEFT(C40,3)="Se ","Recomendado con condiciones de uso",Parametros!$C$10),IF(C37>=Parametros!$A$11,Parametros!$C$11,Parametros!$C$12)))
A43: E. Elementos por mejorar (en el recurso o en su uso)
A44: Técnico:
A45: Pedagógico:
...

Sheet Educ.ar
A1: Instrumento CODA-Rural · Ficha de evaluación de un RED
A2: Amarillo: lo llena el evaluador · Gris: fórmula
A4: A. Identificación del recurso
A5: Nombre del RED | B5: Microcurso «Aprendé a usar el Paquete Google»
A6: Autor / repositorio | B6: Educ.ar (Argentina)
A7: Enlace | B7: https://www.educ.ar/recursos/157415/microcurso-aprende-a-usar-el-paquete-google
A8: Área y grado | B8: Tecnología e Informática · grado 9.°
A9: Evaluador y fecha | B9: Jorge Guillermo Federico Castro Cervantes · octubre de 2026
A11: B. Pruebas de contexto (registrar antes de puntuar)
A12: Prueba | B12: Qué se hace | D12: Resultado | F12: Observación
A13: P1 | B13: Abrir el recurso en un computador con conexión. | D13: Sí | E13: Visor web por secciones y pantalla completa.
A14: P2 | B14: Abrir y usar la actividad principal en un celular Android. | D14: Parcial | E14: Se consulta en el navegador; el visor está pensado para pantalla grande.
A15: P3 | B15: Descargar el recurso y usarlo en modo avión. | D15: Parcial | E15: El contenido se descarga; practicar Gmail, Drive y Calendar exige conexión.
A16: P4 | B16: Registrar el peso de la descarga o el consumo de datos. | D16: Sí | E16: Se registra al descargar en la sala de informática.
A18: C. Rúbrica de valoración (1 a 5 o NA)
A19: Dimensión | B19: Criterio | C19: Indicadores observables | D19: Puntaje | E19: Nivel | F19: Evidencia observada
A20: Pedagógica | B20: C1. Objetivos y coherencia didáctica | C20: • El recurso declara objetivos o resultados de aprendizaje. • Contenidos, actividades y evaluación responden a esos objetivos y al nivel del grupo. | D20: 4 | E20: =IF(D20="","",IF(D20="NA","No aplica",INDEX({"Deficiente","Insuficiente","Aceptable","Bueno","Excelente"},D20))) -> Bueno | F20: Declara qué se aprende (Gmail, Drive y Calendar), pero sus ejemplos se dirigen a la planificación docente; para 9.° hay que reformular las metas.
A21: Pedagógica | B21: C2. Calidad de los contenidos | C21: • La información es correcta y su fuente es identificable. • Es vigente y sus ejemplos sirven en el contexto colombiano y rural. | D21: 4 | E21: =IF(D21="","",IF(D21="NA","No aplica",INDEX({"Deficiente","Insuficiente","Aceptable","Bueno","Excelente"},D21))) -> Bueno | F21: Contenido correcto y de un portal oficial; los ejemplos son de Argentina y deben adaptarse al aula colombiana.
A22: Pedagógica | B22: C3. Reflexión, crítica e innovación | C22: • Plantea problemas, retos o preguntas abiertas. • El estudiante elabora un producto propio. | D22: 3 | E22: =IF(D22="","",IF(D22="NA","No aplica",INDEX({"Deficiente","Insuficiente","Aceptable","Bueno","Excelente"},D22))) -> Aceptable | F22: Es un tutorial: el estudiante repite pasos (crear cuenta, enviar un correo, agendar), sin retos abiertos.
A23: Pedagógica | B23: C4. Interactividad y retroalimentación | C23: • Incluye actividades en las que el sistema responde a lo que hace el estudiante. • La respuesta explica el error o muestra el resultado de inmediato. | D23: 2 | E23: =IF(D23="","",IF(D23="NA","No aplica",INDEX({"Deficiente","Insuficiente","Aceptable","Bueno","Excelente"},D23))) -> Insuficiente | F23: El visor permite avanzar por secciones y ampliar; no hay actividades con retroalimentación automática.
A24: Comunicacional | B24: C5. Motivación | C24: • Conecta con los intereses o la vida diaria del estudiante. • Incluye un reto, un juego o un producto que invita a continuar. | D24: 4 | E24: =IF(D24="","",IF(D24="NA","No aplica",INDEX({"Deficiente","Insuficiente","Aceptable","Bueno","Excelente"},D24))) -> Bueno | F24: Útil para la vida escolar y laboral, pero sin reto ni juego.
A25: Comunicacional | B25: C6. Formato y diseño | C25: • El texto es legible: tamaño y contraste suficientes. • Hay jerarquía visual y espacio en blanco; las imágenes cumplen una función. | D25: 4 | E25: =IF(D25="","",IF(D25="NA","No aplica",INDEX({"Deficiente","Insuficiente","Aceptable","Bueno","Excelente"},D25))) -> Bueno | F25: Pantallas ordenadas, con imágenes de la interfaz que apoyan los pasos.
A26: Comunicacional | B26: C7. Usabilidad | C26: • El estudiante sabe cómo empezar y avanzar sin ayuda. • Siempre sabe dónde está y puede volver atrás. | D26: 4 | E26: =IF(D26="","",IF(D26="NA","No aplica",INDEX({"Deficiente","Insuficiente","Aceptable","Bueno","Excelente"},D26))) -> Bueno | F26: Avance por secciones claro; se recorre sin ayuda.
A27: Comunicacional | B27: C8. Accesibilidad | C27: • Está en español, con lenguaje claro. • Ofrece alternativas: texto para audio o video, versión descargable, ajuste de tamaño. | D27: 4 | E27: =IF(D27="","",IF(D27="NA","No aplica",INDEX({"Deficiente","Insuficiente","Aceptable","Bueno","Excelente"},D27))) -> Bueno | F27: En español y con opción de descarga como formato alternativo.
A28: Técnica y de contexto | B28: C9. Reusabilidad y licencia | C28: • Declara una licencia abierta. • Se puede descargar, adaptar o remezclar. | D28: 4 | E28: =IF(D28="","",IF(D28="NA","No aplica",INDEX({"Deficiente","Insuficiente","Aceptable","Bueno","Excelente"},D28))) -> Bueno | F28: Licencia CC BY-NC-SA declarada; no ofrece archivo fuente editable.
A29: Técnica y de contexto | B29: C10. Interoperabilidad | C29: • Se descarga o exporta en formatos abiertos o comunes. • Se integra al aula virtual institucional (enlace, incrustación o paquete estándar). | D29: 3 | E29: =IF(D29="","",IF(D29="NA","No aplica",INDEX({"Deficiente","Insuficiente","Aceptable","Bueno","Excelente"},D29))) -> Aceptable | F29: Enlace estable y descarga; no está empaquetado en SCORM/IMS.
A30: Técnica y de contexto | B30: C11. Funcionamiento sin conexión | C30: • El recurso se puede descargar completo. • Después de la descarga, la actividad principal funciona en modo avión. | D30: 3 | E30: =IF(D30="","",IF(D30="NA","No aplica",INDEX({"Deficiente","Insuficiente","Aceptable","Bueno","Excelente"},D30))) -> Aceptable | F30: El contenido se descarga, pero practicar Gmail, Drive y Calendar exige conexión.
A31: Técnica y de contexto | B31: C12. Funcionamiento en celular | C31: • La actividad principal se puede realizar en un celular Android. • El recurso es liviano o permite bajo consumo de datos. | D31: 3 | E31: =IF(D31="","",IF(D31="NA","No aplica",INDEX({"Deficiente","Insuficiente","Aceptable","Bueno","Excelente"},D31))) -> Aceptable | F31: Se consulta desde el navegador del celular, pero el visor está pensado para pantalla grande y las prácticas usan la versión web de las herramientas.
A33: D. Resultados (cálculo automático)
A34: Pedagógica | B34: =Parametros!B4 -> 0.4 | C34: =IFERROR(AVERAGEIF($A$20:$A$31,A34,$D$20:$D$31),"") -> 3.25 | D34: ← promedio por dimensión
A35: Comunicacional | B35: =Parametros!B5 -> 0.25 | C35: =IFERROR(AVERAGEIF($A$20:$A$31,A35,$D$20:$D$31),"") -> 4
A36: Técnica y de contexto | B36: =Parametros!B6 -> 0.35 | C36: =IFERROR(AVERAGEIF($A$20:$A$31,A36,$D$20:$D$31),"") -> 3.25
A37: Índice global (IGC) | C37: =IF(COUNT(D20:D31)=0,"",IFERROR(SUMPRODUCT(B34:B36,C34:C36)/SUM(B34:B36),"")) -> 3.4375
A38: Porcentaje | C38: =IFERROR(C37/5,"") -> 0.6875
A39: Nivel | C39: =IF(C37="","",IF(C37>=Parametros!$A$10,Parametros!$B$10,IF(C37>=Parametros!$A$11,Parametros!$B$11,Parametros!$B$12))) -> Medio
A40: Regla de contexto | C40: =IF(C37="","",IF(OR(AND(ISNUMBER(D30),D30<=2),AND(ISNUMBER(D31),D31<=2)),"Se activa (C11 o C12 ≤ 2)","No se activa")) -> No se activa
A41: Decisión | C41: =IF(C37="","",IF(C37>=Parametros!$A$10,IF(LEFT(C40,3)="Se ","Recomendado con condiciones de uso",Parametros!$C$10),IF(C37>=Parametros!$A$11,Parametros!$C$11,Parametros!$C$12))) -> Recomendado con ajustes
A43: E. Elementos por mejorar (en el recurso o en su uso)
A44: Técnico: ofrecer una versión liviana descargable (PDF o HTML) y un tutorial de las apps de Gmail y Drive para celular.
A45: Pedagógico: agregar actividades de práctica con retroalimentación y metas para estudiantes de 9.°.
...

Sheet Scratch
A1: Instrumento CODA-Rural · Ficha de evaluación de un RED
A2: Amarillo: lo llena el evaluador · Gris: fórmula
A4: A. Identificación del recurso
A5: Nombre del RED | B5: Scratch: entorno de programación por bloques
A6: Autor / repositorio | B6: Lifelong Kindergarten Group, MIT Media Lab
A7: Enlace | B7: https://scratch.mit.edu/
A8: Área y grado | B8: Tecnología e Informática · grado 9.°
A9: Evaluador y fecha | B9: Jorge Guillermo Federico Castro Cervantes · octubre de 2026
A11: B. Pruebas de contexto (registrar antes de puntuar)
A12: Prueba | B12: Qué se hace | D12: Resultado | F12: Observación
A13: P1 | B13: Abrir el recurso en un computador con conexión. | D13: Sí | E13: Editor en línea completo.
A14: P2 | B14: Abrir y usar la actividad principal en un celular Android. | D14: No | E14: En celular solo se ven proyectos; no se crean ni editan (FAQ de Scratch).
A15: P3 | B15: Descargar el recurso y usarlo en modo avión. | D15: Parcial | E15: Aplicación de escritorio sin conexión solo para Windows y Mac.
A16: P4 | B16: Registrar el peso de la descarga o el consumo de datos. | D16: Sí | E16: Se registra al instalar la aplicación de escritorio.
A18: C. Rúbrica de valoración (1 a 5 o NA)
A19: Dimensión | B19: Criterio | C19: Indicadores observables | D19: Puntaje | E19: Nivel | F19: Evidencia observada
A20: Pedagógica | B20: C1. Objetivos y coherencia didáctica | C20: • El recurso declara objetivos o resultados de aprendizaje. • Contenidos, actividades y evaluación responden a esos objetivos y al nivel del grupo. | D20: 4 | E20: =IF(D20="","",IF(D20="NA","No aplica",INDEX({"Deficiente","Insuficiente","Aceptable","Bueno","Excelente"},D20))) -> Bueno | F20: Es un entorno abierto: los tutoriales tienen metas, pero los objetivos de clase los define el docente.
A21: Pedagógica | B21: C2. Calidad de los contenidos | C21: • La información es correcta y su fuente es identificable. • Es vigente y sus ejemplos sirven en el contexto colombiano y rural. | D21: 5 | E21: =IF(D21="","",IF(D21="NA","No aplica",INDEX({"Deficiente","Insuficiente","Aceptable","Bueno","Excelente"},D21))) -> Excelente | F21: Entorno sólido, documentado y en uso internacional.
A22: Pedagógica | B22: C3. Reflexión, crítica e innovación | C22: • Plantea problemas, retos o preguntas abiertas. • El estudiante elabora un producto propio. | D22: 5 | E22: =IF(D22="","",IF(D22="NA","No aplica",INDEX({"Deficiente","Insuficiente","Aceptable","Bueno","Excelente"},D22))) -> Excelente | F22: El estudiante crea juegos e historias propios, los comparte y los remezcla.
A23: Pedagógica | B23: C4. Interactividad y retroalimentación | C23: • Incluye actividades en las que el sistema responde a lo que hace el estudiante. • La respuesta explica el error o muestra el resultado de inmediato. | D23: 5 | E23: =IF(D23="","",IF(D23="NA","No aplica",INDEX({"Deficiente","Insuficiente","Aceptable","Bueno","Excelente"},D23))) -> Excelente | F23: Cada bloque se ejecuta y el resultado se ve al instante en el escenario.
A24: Comunicacional | B24: C5. Motivación | C24: • Conecta con los intereses o la vida diaria del estudiante. • Incluye un reto, un juego o un producto que invita a continuar. | D24: 5 | E24: =IF(D24="","",IF(D24="NA","No aplica",INDEX({"Deficiente","Insuficiente","Aceptable","Bueno","Excelente"},D24))) -> Excelente | F24: Crear, jugar y compartir sostiene el interés.
A25: Comunicacional | B25: C6. Formato y diseño | C25: • El texto es legible: tamaño y contraste suficientes. • Hay jerarquía visual y espacio en blanco; las imágenes cumplen una función. | D25: 5 | E25: =IF(D25="","",IF(D25="NA","No aplica",INDEX({"Deficiente","Insuficiente","Aceptable","Bueno","Excelente"},D25))) -> Excelente | F25: Editor claro: escenario, objetos y bloques por colores.
A26: Comunicacional | B26: C7. Usabilidad | C26: • El estudiante sabe cómo empezar y avanzar sin ayuda. • Siempre sabe dónde está y puede volver atrás. | D26: 5 | E26: =IF(D26="","",IF(D26="NA","No aplica",INDEX({"Deficiente","Insuficiente","Aceptable","Bueno","Excelente"},D26))) -> Excelente | F26: Arrastrar y soltar; se usa solo desde el primer intento.
A27: Comunicacional | B27: C8. Accesibilidad | C27: • Está en español, con lenguaje claro. • Ofrece alternativas: texto para audio o video, versión descargable, ajuste de tamaño. | D27: 4 | E27: =IF(D27="","",IF(D27="NA","No aplica",INDEX({"Deficiente","Insuficiente","Aceptable","Bueno","Excelente"},D27))) -> Bueno | F27: En español y con tutoriales en video y texto; depende mucho de lo visual.
A28: Técnica y de contexto | B28: C9. Reusabilidad y licencia | C28: • Declara una licencia abierta. • Se puede descargar, adaptar o remezclar. | D28: 5 | E28: =IF(D28="","",IF(D28="NA","No aplica",INDEX({"Deficiente","Insuficiente","Aceptable","Bueno","Excelente"},D28))) -> Excelente | F28: Proyectos compartidos bajo licencia Creative Commons Compartir Igual; se remezclan.
A29: Técnica y de contexto | B29: C10. Interoperabilidad | C29: • Se descarga o exporta en formatos abiertos o comunes. • Se integra al aula virtual institucional (enlace, incrustación o paquete estándar). | D29: 4 | E29: =IF(D29="","",IF(D29="NA","No aplica",INDEX({"Deficiente","Insuficiente","Aceptable","Bueno","Excelente"},D29))) -> Bueno | F29: Exporta archivos .sb3 y los proyectos se pueden incrustar; no ofrece SCORM.
A30: Técnica y de contexto | B30: C11. Funcionamiento sin conexión | C30: • El recurso se puede descargar completo. • Después de la descarga, la actividad principal funciona en modo avión. | D30: 4 | E30: =IF(D30="","",IF(D30="NA","No aplica",INDEX({"Deficiente","Insuficiente","Aceptable","Bueno","Excelente"},D30))) -> Bueno | F30: La aplicación de escritorio funciona sin conexión, pero solo en Windows y Mac (Scratch Foundation, s. f.).
A31: Técnica y de contexto | B31: C12. Funcionamiento en celular | C31: • La actividad principal se puede realizar en un celular Android. • El recurso es liviano o permite bajo consumo de datos. | D31: 1 | E31: =IF(D31="","",IF(D31="NA","No aplica",INDEX({"Deficiente","Insuficiente","Aceptable","Bueno","Excelente"},D31))) -> Deficiente | F31: En el celular solo se pueden ver proyectos; no se pueden crear ni editar (Scratch Foundation, s. f.).
A33: D. Resultados (cálculo automático)
A34: Pedagógica | B34: =Parametros!B4 -> 0.4 | C34: =IFERROR(AVERAGEIF($A$20:$A$31,A34,$D$20:$D$31),"") -> 4.75 | D34: ← promedio por dimensión
A35: Comunicacional | B35: =Parametros!B5 -> 0.25 | C35: =IFERROR(AVERAGEIF($A$20:$A$31,A35,$D$20:$D$31),"") -> 4.75
A36: Técnica y de contexto | B36: =Parametros!B6 -> 0.35 | C36: =IFERROR(AVERAGEIF($A$20:$A$31,A36,$D$20:$D$31),"") -> 3.5
A37: Índice global (IGC) | C37: =IF(COUNT(D20:D31)=0,"",IFERROR(SUMPRODUCT(B34:B36,C34:C36)/SUM(B34:B36),"")) -> 4.3125
A38: Porcentaje | C38: =IFERROR(C37/5,"") -> 0.8625
A39: Nivel | C39: =IF(C37="","",IF(C37>=Parametros!$A$10,Parametros!$B$10,IF(C37>=Parametros!$A$11,Parametros!$B$11,Parametros!$B$12))) -> Alto
A40: Regla de contexto | C40: =IF(C37="","",IF(OR(AND(ISNUMBER(D30),D30<=2),AND(ISNUMBER(D31),D31<=2)),"Se activa (C11 o C12 ≤ 2)","No se activa")) -> Se activa (C11 o C12 ≤ 2)
A41: Decisión | C41: =IF(C37="","",IF(C37>=Parametros!$A$10,IF(LEFT(C40,3)="Se ","Recomendado con condiciones de uso",Parametros!$C$10),IF(C37>=Parametros!$A$11,Parametros!$C$11,Parametros!$C$12))) -> Recomendado con condiciones de uso
A43: E. Elementos por mejorar (en el recurso o en su uso)
A44: Técnico: instalar la aplicación de escritorio en los equipos Windows de la sala; preparar proyectos para ver en celular.
A45: Pedagógico: el docente define metas por sesión y retos con criterios de logro.
...

Sheet Comparacion
A1: Comparación con los modelos aplicados en el Entregable 1 (escala 1 a 5)
A3: Recurso | B3: COdA (E1) | C3: LORI (E1) | D3: Reeves (E1) | E3: CODA-Rural (E2) | F3: Decisión CODA-Rural
A4: Educ.ar | B4: 3.9 | C4: 4.1 | D4: 3.6 | E4: ='Educ.ar'!C37 -> 3.4375 | F4: ='Educ.ar'!C41 -> Recomendado con ajustes
A5: Scratch | B5: 4.7 | C5: 4.7 | D5: 4.9 | E5: =Scratch!C37 -> 4.3125 | F5: =Scratch!C41 -> Recomendado con condiciones de uso
A7: Fuente de COdA, LORI y Reeves: Castro Cervantes (2026), Entregable 1, tablas de aplicación (puntuación final de cada modelo).
A8: Diferencia CODA-Rural − promedio de los tres modelos del E1:
A9: Educ.ar | B9: =E4-AVERAGE(B4:D4) -> -0.42916667
A10: Scratch | B10: =E5-AVERAGE(B5:D5) -> -0.45416667
